# 数据分析模块修复文档

## 问题概述

在数据库自动更新过程中，"数据分析"步骤失败，具体错误为：

```
ImportError: cannot import name 'analyze_data' from 'analysis' (F:\pj\bbs_data\py\analysis.py)
```

这表明在尝试从analysis.py中导入analyze_data函数时出错，原因是该函数不存在。

## 解决方案

1. 在analysis.py中增加了`analyze_data`函数作为外部调用的入口点：
   ```python
   def analyze_data(debug=False):
       """外部调用的入口点函数"""
       try:
           print("开始执行数据分析...")
           if debug:
               print("调试模式：打印更多日志信息")
           
           result_df = main()
           
           print(f"数据分析完成，生成了 {len(result_df)} 条分析记录")
           return True
       except Exception as e:
           print(f"数据分析执行出错: {str(e)}")
           if debug:
               import traceback
               traceback.print_exc()
           return False
   ```

2. 修改main函数，使其返回结果数据，方便analyze_data函数使用：
   ```python
   def main():
       # ...existing code...
       
       # 保存结果到CSV文件
       output_file = PROCESSED_DIR / 'import.csv'
       final_df.to_csv(output_file, index=False, encoding='utf-8-sig')
       print(f"\n分析完成，结果已保存到：{output_file}")
       print(f"数据导入文件：{output_file}")
       
       return final_df  # 返回结果数据
   ```

## 测试验证

创建了测试脚本`test_analysis.py`，进行了以下测试：

1. **测试analyze_data函数导入和执行**：
   - 验证函数是否可以被正确导入
   - 验证函数是否可以成功执行并返回正确结果

2. **测试直接执行analysis.py脚本**：
   - 验证脚本是否可以独立运行
   - 验证脚本执行后是否生成了正确的输出文件

两项测试均成功通过，表明修复有效。

## 使用方法

分析模块的使用方法现在有两种：

1. **直接执行脚本**（原有方式）：
   ```
   python py/analysis.py
   ```

2. **通过代码调用**（新增方式）：
   ```python
   from analysis import analyze_data
   success = analyze_data(debug=True)  # debug参数可选
   ```

debug参数设为True时，会在出错时打印详细的堆栈跟踪信息，便于调试。

## 注意事项

1. 函数返回值为布尔型，表示执行是否成功
2. 分析结果保存在`data/processed/import.csv`文件中
3. 分析过程中会生成其他文件，如`post_ranking.csv`和`author_ranking.csv` 